package exception;

import ex.com.exceptions;

private class ExceptionsExample{
	
	
	public void callDivide(){
    	try {
        	int result = divide(2,1);
            System.out.println(result);
        } catch (BadNumberException e) {
            //do something clever with the exception
            System.out.println(e.getMessage());
        }
        System.out.println("Division attempt done");
    }
    
    public void openFile(){
    	FileReader reader = null;
        try {
        	reader = new FileReader("someFile");
            int i=0;
            while(i != -1){
                i = reader.read();
                System.out.println((char) i );
            }
        } catch (IOException e) {
            //do something clever with the exception
        } finally {
            if(reader != null){
                try {
                    reader.close();
                } catch (IOException e) {
                    //do something clever with the exception
                }
            }
            System.out.println("--- File End ---");
        }
    }
    
    public void putElementOnArray(){
    	int[] array = new int[3];
        try{
            for(int i=0;i<4;++i){
                array[i] = i;
            }
            System.out.println(array);
        }
        catch(ArrayIndexOutOfBoundsException e){
            //printed just to inform that we have entered the catch block
            System.out.println("Oops, we went to far, better go back to 0!");
        }
    }
}